INFO 2025-09-28 18:55:59,291 finance_agent 38961 8680163328 Finance Agent loaded with model: gpt2
INFO 2025-09-28 18:55:59,740 medical_agent 38961 8680163328 Medical Agent loaded with model: gpt2
INFO 2025-09-28 18:55:59,742 orchestrator 38961 8680163328 Orchestrator initialized successfully
WARNING 2025-09-28 18:55:59,743 faithfulness 38961 8680163328 sentence-transformers not available, using token-based metrics only
WARNING 2025-09-28 18:55:59,743 safety 38961 8680163328 Safety config not found: /Users/somesh/Library/CloudStorage/OneDrive-PaceUniversity/Fair-Agent/config/safety_keywords.yaml
INFO 2025-09-28 18:55:59,743 services 38961 8680163328 FAIR-Agent system initialized successfully
INFO 2025-09-28 18:56:03,396 finance_agent 38991 8680163328 Finance Agent loaded with model: gpt2
INFO 2025-09-28 18:56:03,811 medical_agent 38991 8680163328 Medical Agent loaded with model: gpt2
INFO 2025-09-28 18:56:03,811 orchestrator 38991 8680163328 Orchestrator initialized successfully
WARNING 2025-09-28 18:56:03,811 faithfulness 38991 8680163328 sentence-transformers not available, using token-based metrics only
WARNING 2025-09-28 18:56:03,811 safety 38991 8680163328 Safety config not found: /Users/somesh/Library/CloudStorage/OneDrive-PaceUniversity/Fair-Agent/config/safety_keywords.yaml
INFO 2025-09-28 18:56:03,811 services 38991 8680163328 FAIR-Agent system initialized successfully
INFO 2025-09-28 18:56:03,818 autoreload 38991 8680163328 Watching for file changes with StatReloader
ERROR 2025-09-28 18:56:09,995 log 38991 6239154176 Internal Server Error: /
Traceback (most recent call last):
  File "/Users/somesh/Library/CloudStorage/OneDrive-PaceUniversity/Fair-Agent/.venv/lib/python3.13/site-packages/django/db/backends/utils.py", line 89, in _execute
    return self.cursor.execute(sql, params)
           ~~~~~~~~~~~~~~~~~~~^^^^^^^^^^^^^
  File "/Users/somesh/Library/CloudStorage/OneDrive-PaceUniversity/Fair-Agent/.venv/lib/python3.13/site-packages/django/db/backends/sqlite3/base.py", line 328, in execute
    return super().execute(query, params)
           ~~~~~~~~~~~~~~~^^^^^^^^^^^^^^^
sqlite3.OperationalError: no such table: fair_agent_app_queryrecord

The above exception was the direct cause of the following exception:

Traceback (most recent call last):
  File "/Users/somesh/Library/CloudStorage/OneDrive-PaceUniversity/Fair-Agent/.venv/lib/python3.13/site-packages/django/core/handlers/exception.py", line 55, in inner
    response = get_response(request)
  File "/Users/somesh/Library/CloudStorage/OneDrive-PaceUniversity/Fair-Agent/.venv/lib/python3.13/site-packages/django/core/handlers/base.py", line 197, in _get_response
    response = wrapped_callback(request, *callback_args, **callback_kwargs)
  File "/Users/somesh/Library/CloudStorage/OneDrive-PaceUniversity/Fair-Agent/.venv/lib/python3.13/site-packages/django/views/generic/base.py", line 105, in view
    return self.dispatch(request, *args, **kwargs)
           ~~~~~~~~~~~~~^^^^^^^^^^^^^^^^^^^^^^^^^^
  File "/Users/somesh/Library/CloudStorage/OneDrive-PaceUniversity/Fair-Agent/.venv/lib/python3.13/site-packages/django/views/generic/base.py", line 144, in dispatch
    return handler(request, *args, **kwargs)
  File "/Users/somesh/Library/CloudStorage/OneDrive-PaceUniversity/Fair-Agent/.venv/lib/python3.13/site-packages/django/views/generic/base.py", line 228, in get
    context = self.get_context_data(**kwargs)
  File "/Users/somesh/Library/CloudStorage/OneDrive-PaceUniversity/Fair-Agent/webapp/fair_agent_app/views.py", line 46, in get_context_data
    total_queries = QueryRecord.objects.count()
  File "/Users/somesh/Library/CloudStorage/OneDrive-PaceUniversity/Fair-Agent/.venv/lib/python3.13/site-packages/django/db/models/manager.py", line 87, in manager_method
    return getattr(self.get_queryset(), name)(*args, **kwargs)
           ~~~~~~~~~~~~~~~~~~~~~~~~~~~~~~~~~~^^^^^^^^^^^^^^^^^
  File "/Users/somesh/Library/CloudStorage/OneDrive-PaceUniversity/Fair-Agent/.venv/lib/python3.13/site-packages/django/db/models/query.py", line 608, in count
    return self.query.get_count(using=self.db)
           ~~~~~~~~~~~~~~~~~~~~^^^^^^^^^^^^^^^
  File "/Users/somesh/Library/CloudStorage/OneDrive-PaceUniversity/Fair-Agent/.venv/lib/python3.13/site-packages/django/db/models/sql/query.py", line 568, in get_count
    return obj.get_aggregation(using, {"__count": Count("*")})["__count"]
           ~~~~~~~~~~~~~~~~~~~^^^^^^^^^^^^^^^^^^^^^^^^^^^^^^^^
  File "/Users/somesh/Library/CloudStorage/OneDrive-PaceUniversity/Fair-Agent/.venv/lib/python3.13/site-packages/django/db/models/sql/query.py", line 554, in get_aggregation
    result = compiler.execute_sql(SINGLE)
  File "/Users/somesh/Library/CloudStorage/OneDrive-PaceUniversity/Fair-Agent/.venv/lib/python3.13/site-packages/django/db/models/sql/compiler.py", line 1562, in execute_sql
    cursor.execute(sql, params)
    ~~~~~~~~~~~~~~^^^^^^^^^^^^^
  File "/Users/somesh/Library/CloudStorage/OneDrive-PaceUniversity/Fair-Agent/.venv/lib/python3.13/site-packages/django/db/backends/utils.py", line 102, in execute
    return super().execute(sql, params)
           ~~~~~~~~~~~~~~~^^^^^^^^^^^^^
  File "/Users/somesh/Library/CloudStorage/OneDrive-PaceUniversity/Fair-Agent/.venv/lib/python3.13/site-packages/django/db/backends/utils.py", line 67, in execute
    return self._execute_with_wrappers(
           ~~~~~~~~~~~~~~~~~~~~~~~~~~~^
        sql, params, many=False, executor=self._execute
        ^^^^^^^^^^^^^^^^^^^^^^^^^^^^^^^^^^^^^^^^^^^^^^^
    )
    ^
  File "/Users/somesh/Library/CloudStorage/OneDrive-PaceUniversity/Fair-Agent/.venv/lib/python3.13/site-packages/django/db/backends/utils.py", line 80, in _execute_with_wrappers
    return executor(sql, params, many, context)
  File "/Users/somesh/Library/CloudStorage/OneDrive-PaceUniversity/Fair-Agent/.venv/lib/python3.13/site-packages/django/db/backends/utils.py", line 84, in _execute
    with self.db.wrap_database_errors:
         ^^^^^^^^^^^^^^^^^^^^^^^^^^^^
  File "/Users/somesh/Library/CloudStorage/OneDrive-PaceUniversity/Fair-Agent/.venv/lib/python3.13/site-packages/django/db/utils.py", line 91, in __exit__
    raise dj_exc_value.with_traceback(traceback) from exc_value
  File "/Users/somesh/Library/CloudStorage/OneDrive-PaceUniversity/Fair-Agent/.venv/lib/python3.13/site-packages/django/db/backends/utils.py", line 89, in _execute
    return self.cursor.execute(sql, params)
           ~~~~~~~~~~~~~~~~~~~^^^^^^^^^^^^^
  File "/Users/somesh/Library/CloudStorage/OneDrive-PaceUniversity/Fair-Agent/.venv/lib/python3.13/site-packages/django/db/backends/sqlite3/base.py", line 328, in execute
    return super().execute(query, params)
           ~~~~~~~~~~~~~~~^^^^^^^^^^^^^^^
django.db.utils.OperationalError: no such table: fair_agent_app_queryrecord
ERROR 2025-09-28 18:56:09,998 basehttp 38991 6239154176 "GET /?id=6922b48c-a19b-43c5-b4dc-fec650371f80&vscodeBrowserReqId=1759085769959 HTTP/1.1" 500 149061
ERROR 2025-09-28 18:56:15,193 log 38991 6255980544 Internal Server Error: /query/
Traceback (most recent call last):
  File "/Users/somesh/Library/CloudStorage/OneDrive-PaceUniversity/Fair-Agent/.venv/lib/python3.13/site-packages/django/contrib/sessions/backends/base.py", line 187, in _get_session
    return self._session_cache
           ^^^^^^^^^^^^^^^^^^^
AttributeError: 'SessionStore' object has no attribute '_session_cache'

During handling of the above exception, another exception occurred:

Traceback (most recent call last):
  File "/Users/somesh/Library/CloudStorage/OneDrive-PaceUniversity/Fair-Agent/.venv/lib/python3.13/site-packages/django/db/backends/utils.py", line 89, in _execute
    return self.cursor.execute(sql, params)
           ~~~~~~~~~~~~~~~~~~~^^^^^^^^^^^^^
  File "/Users/somesh/Library/CloudStorage/OneDrive-PaceUniversity/Fair-Agent/.venv/lib/python3.13/site-packages/django/db/backends/sqlite3/base.py", line 328, in execute
    return super().execute(query, params)
           ~~~~~~~~~~~~~~~^^^^^^^^^^^^^^^
sqlite3.OperationalError: no such table: django_session

The above exception was the direct cause of the following exception:

Traceback (most recent call last):
  File "/Users/somesh/Library/CloudStorage/OneDrive-PaceUniversity/Fair-Agent/.venv/lib/python3.13/site-packages/django/core/handlers/exception.py", line 55, in inner
    response = get_response(request)
  File "/Users/somesh/Library/CloudStorage/OneDrive-PaceUniversity/Fair-Agent/.venv/lib/python3.13/site-packages/django/core/handlers/base.py", line 197, in _get_response
    response = wrapped_callback(request, *callback_args, **callback_kwargs)
  File "/Users/somesh/Library/CloudStorage/OneDrive-PaceUniversity/Fair-Agent/.venv/lib/python3.13/site-packages/django/views/generic/base.py", line 105, in view
    return self.dispatch(request, *args, **kwargs)
           ~~~~~~~~~~~~~^^^^^^^^^^^^^^^^^^^^^^^^^^
  File "/Users/somesh/Library/CloudStorage/OneDrive-PaceUniversity/Fair-Agent/.venv/lib/python3.13/site-packages/django/views/generic/base.py", line 144, in dispatch
    return handler(request, *args, **kwargs)
  File "/Users/somesh/Library/CloudStorage/OneDrive-PaceUniversity/Fair-Agent/.venv/lib/python3.13/site-packages/django/views/generic/base.py", line 228, in get
    context = self.get_context_data(**kwargs)
  File "/Users/somesh/Library/CloudStorage/OneDrive-PaceUniversity/Fair-Agent/webapp/fair_agent_app/views.py", line 65, in get_context_data
    session_id = self.request.session.get('fair_agent_session_id')
  File "/Users/somesh/Library/CloudStorage/OneDrive-PaceUniversity/Fair-Agent/.venv/lib/python3.13/site-packages/django/contrib/sessions/backends/base.py", line 68, in get
    return self._session.get(key, default)
           ^^^^^^^^^^^^^
  File "/Users/somesh/Library/CloudStorage/OneDrive-PaceUniversity/Fair-Agent/.venv/lib/python3.13/site-packages/django/contrib/sessions/backends/base.py", line 192, in _get_session
    self._session_cache = self.load()
                          ~~~~~~~~~^^
  File "/Users/somesh/Library/CloudStorage/OneDrive-PaceUniversity/Fair-Agent/.venv/lib/python3.13/site-packages/django/contrib/sessions/backends/db.py", line 42, in load
    s = self._get_session_from_db()
  File "/Users/somesh/Library/CloudStorage/OneDrive-PaceUniversity/Fair-Agent/.venv/lib/python3.13/site-packages/django/contrib/sessions/backends/db.py", line 32, in _get_session_from_db
    return self.model.objects.get(
           ~~~~~~~~~~~~~~~~~~~~~~^
        session_key=self.session_key, expire_date__gt=timezone.now()
        ^^^^^^^^^^^^^^^^^^^^^^^^^^^^^^^^^^^^^^^^^^^^^^^^^^^^^^^^^^^^
    )
    ^
  File "/Users/somesh/Library/CloudStorage/OneDrive-PaceUniversity/Fair-Agent/.venv/lib/python3.13/site-packages/django/db/models/manager.py", line 87, in manager_method
    return getattr(self.get_queryset(), name)(*args, **kwargs)
           ~~~~~~~~~~~~~~~~~~~~~~~~~~~~~~~~~~^^^^^^^^^^^^^^^^^
  File "/Users/somesh/Library/CloudStorage/OneDrive-PaceUniversity/Fair-Agent/.venv/lib/python3.13/site-packages/django/db/models/query.py", line 633, in get
    num = len(clone)
  File "/Users/somesh/Library/CloudStorage/OneDrive-PaceUniversity/Fair-Agent/.venv/lib/python3.13/site-packages/django/db/models/query.py", line 380, in __len__
    self._fetch_all()
    ~~~~~~~~~~~~~~~^^
  File "/Users/somesh/Library/CloudStorage/OneDrive-PaceUniversity/Fair-Agent/.venv/lib/python3.13/site-packages/django/db/models/query.py", line 1881, in _fetch_all
    self._result_cache = list(self._iterable_class(self))
                         ~~~~^^^^^^^^^^^^^^^^^^^^^^^^^^^^
  File "/Users/somesh/Library/CloudStorage/OneDrive-PaceUniversity/Fair-Agent/.venv/lib/python3.13/site-packages/django/db/models/query.py", line 91, in __iter__
    results = compiler.execute_sql(
        chunked_fetch=self.chunked_fetch, chunk_size=self.chunk_size
    )
  File "/Users/somesh/Library/CloudStorage/OneDrive-PaceUniversity/Fair-Agent/.venv/lib/python3.13/site-packages/django/db/models/sql/compiler.py", line 1562, in execute_sql
    cursor.execute(sql, params)
    ~~~~~~~~~~~~~~^^^^^^^^^^^^^
  File "/Users/somesh/Library/CloudStorage/OneDrive-PaceUniversity/Fair-Agent/.venv/lib/python3.13/site-packages/django/db/backends/utils.py", line 102, in execute
    return super().execute(sql, params)
           ~~~~~~~~~~~~~~~^^^^^^^^^^^^^
  File "/Users/somesh/Library/CloudStorage/OneDrive-PaceUniversity/Fair-Agent/.venv/lib/python3.13/site-packages/django/db/backends/utils.py", line 67, in execute
    return self._execute_with_wrappers(
           ~~~~~~~~~~~~~~~~~~~~~~~~~~~^
        sql, params, many=False, executor=self._execute
        ^^^^^^^^^^^^^^^^^^^^^^^^^^^^^^^^^^^^^^^^^^^^^^^
    )
    ^
  File "/Users/somesh/Library/CloudStorage/OneDrive-PaceUniversity/Fair-Agent/.venv/lib/python3.13/site-packages/django/db/backends/utils.py", line 80, in _execute_with_wrappers
    return executor(sql, params, many, context)
  File "/Users/somesh/Library/CloudStorage/OneDrive-PaceUniversity/Fair-Agent/.venv/lib/python3.13/site-packages/django/db/backends/utils.py", line 84, in _execute
    with self.db.wrap_database_errors:
         ^^^^^^^^^^^^^^^^^^^^^^^^^^^^
  File "/Users/somesh/Library/CloudStorage/OneDrive-PaceUniversity/Fair-Agent/.venv/lib/python3.13/site-packages/django/db/utils.py", line 91, in __exit__
    raise dj_exc_value.with_traceback(traceback) from exc_value
  File "/Users/somesh/Library/CloudStorage/OneDrive-PaceUniversity/Fair-Agent/.venv/lib/python3.13/site-packages/django/db/backends/utils.py", line 89, in _execute
    return self.cursor.execute(sql, params)
           ~~~~~~~~~~~~~~~~~~~^^^^^^^^^^^^^
  File "/Users/somesh/Library/CloudStorage/OneDrive-PaceUniversity/Fair-Agent/.venv/lib/python3.13/site-packages/django/db/backends/sqlite3/base.py", line 328, in execute
    return super().execute(query, params)
           ~~~~~~~~~~~~~~~^^^^^^^^^^^^^^^
django.db.utils.OperationalError: no such table: django_session
ERROR 2025-09-28 18:56:15,202 basehttp 38991 6255980544 "GET /query/ HTTP/1.1" 500 173787
ERROR 2025-09-28 18:56:19,380 log 38991 6255980544 Internal Server Error: /
Traceback (most recent call last):
  File "/Users/somesh/Library/CloudStorage/OneDrive-PaceUniversity/Fair-Agent/.venv/lib/python3.13/site-packages/django/db/backends/utils.py", line 89, in _execute
    return self.cursor.execute(sql, params)
           ~~~~~~~~~~~~~~~~~~~^^^^^^^^^^^^^
  File "/Users/somesh/Library/CloudStorage/OneDrive-PaceUniversity/Fair-Agent/.venv/lib/python3.13/site-packages/django/db/backends/sqlite3/base.py", line 328, in execute
    return super().execute(query, params)
           ~~~~~~~~~~~~~~~^^^^^^^^^^^^^^^
sqlite3.OperationalError: no such table: fair_agent_app_queryrecord

The above exception was the direct cause of the following exception:

Traceback (most recent call last):
  File "/Users/somesh/Library/CloudStorage/OneDrive-PaceUniversity/Fair-Agent/.venv/lib/python3.13/site-packages/django/core/handlers/exception.py", line 55, in inner
    response = get_response(request)
  File "/Users/somesh/Library/CloudStorage/OneDrive-PaceUniversity/Fair-Agent/.venv/lib/python3.13/site-packages/django/core/handlers/base.py", line 197, in _get_response
    response = wrapped_callback(request, *callback_args, **callback_kwargs)
  File "/Users/somesh/Library/CloudStorage/OneDrive-PaceUniversity/Fair-Agent/.venv/lib/python3.13/site-packages/django/views/generic/base.py", line 105, in view
    return self.dispatch(request, *args, **kwargs)
           ~~~~~~~~~~~~~^^^^^^^^^^^^^^^^^^^^^^^^^^
  File "/Users/somesh/Library/CloudStorage/OneDrive-PaceUniversity/Fair-Agent/.venv/lib/python3.13/site-packages/django/views/generic/base.py", line 144, in dispatch
    return handler(request, *args, **kwargs)
  File "/Users/somesh/Library/CloudStorage/OneDrive-PaceUniversity/Fair-Agent/.venv/lib/python3.13/site-packages/django/views/generic/base.py", line 228, in get
    context = self.get_context_data(**kwargs)
  File "/Users/somesh/Library/CloudStorage/OneDrive-PaceUniversity/Fair-Agent/webapp/fair_agent_app/views.py", line 46, in get_context_data
    total_queries = QueryRecord.objects.count()
  File "/Users/somesh/Library/CloudStorage/OneDrive-PaceUniversity/Fair-Agent/.venv/lib/python3.13/site-packages/django/db/models/manager.py", line 87, in manager_method
    return getattr(self.get_queryset(), name)(*args, **kwargs)
           ~~~~~~~~~~~~~~~~~~~~~~~~~~~~~~~~~~^^^^^^^^^^^^^^^^^
  File "/Users/somesh/Library/CloudStorage/OneDrive-PaceUniversity/Fair-Agent/.venv/lib/python3.13/site-packages/django/db/models/query.py", line 608, in count
    return self.query.get_count(using=self.db)
           ~~~~~~~~~~~~~~~~~~~~^^^^^^^^^^^^^^^
  File "/Users/somesh/Library/CloudStorage/OneDrive-PaceUniversity/Fair-Agent/.venv/lib/python3.13/site-packages/django/db/models/sql/query.py", line 568, in get_count
    return obj.get_aggregation(using, {"__count": Count("*")})["__count"]
           ~~~~~~~~~~~~~~~~~~~^^^^^^^^^^^^^^^^^^^^^^^^^^^^^^^^
  File "/Users/somesh/Library/CloudStorage/OneDrive-PaceUniversity/Fair-Agent/.venv/lib/python3.13/site-packages/django/db/models/sql/query.py", line 554, in get_aggregation
    result = compiler.execute_sql(SINGLE)
  File "/Users/somesh/Library/CloudStorage/OneDrive-PaceUniversity/Fair-Agent/.venv/lib/python3.13/site-packages/django/db/models/sql/compiler.py", line 1562, in execute_sql
    cursor.execute(sql, params)
    ~~~~~~~~~~~~~~^^^^^^^^^^^^^
  File "/Users/somesh/Library/CloudStorage/OneDrive-PaceUniversity/Fair-Agent/.venv/lib/python3.13/site-packages/django/db/backends/utils.py", line 102, in execute
    return super().execute(sql, params)
           ~~~~~~~~~~~~~~~^^^^^^^^^^^^^
  File "/Users/somesh/Library/CloudStorage/OneDrive-PaceUniversity/Fair-Agent/.venv/lib/python3.13/site-packages/django/db/backends/utils.py", line 67, in execute
    return self._execute_with_wrappers(
           ~~~~~~~~~~~~~~~~~~~~~~~~~~~^
        sql, params, many=False, executor=self._execute
        ^^^^^^^^^^^^^^^^^^^^^^^^^^^^^^^^^^^^^^^^^^^^^^^
    )
    ^
  File "/Users/somesh/Library/CloudStorage/OneDrive-PaceUniversity/Fair-Agent/.venv/lib/python3.13/site-packages/django/db/backends/utils.py", line 80, in _execute_with_wrappers
    return executor(sql, params, many, context)
  File "/Users/somesh/Library/CloudStorage/OneDrive-PaceUniversity/Fair-Agent/.venv/lib/python3.13/site-packages/django/db/backends/utils.py", line 84, in _execute
    with self.db.wrap_database_errors:
         ^^^^^^^^^^^^^^^^^^^^^^^^^^^^
  File "/Users/somesh/Library/CloudStorage/OneDrive-PaceUniversity/Fair-Agent/.venv/lib/python3.13/site-packages/django/db/utils.py", line 91, in __exit__
    raise dj_exc_value.with_traceback(traceback) from exc_value
  File "/Users/somesh/Library/CloudStorage/OneDrive-PaceUniversity/Fair-Agent/.venv/lib/python3.13/site-packages/django/db/backends/utils.py", line 89, in _execute
    return self.cursor.execute(sql, params)
           ~~~~~~~~~~~~~~~~~~~^^^^^^^^^^^^^
  File "/Users/somesh/Library/CloudStorage/OneDrive-PaceUniversity/Fair-Agent/.venv/lib/python3.13/site-packages/django/db/backends/sqlite3/base.py", line 328, in execute
    return super().execute(query, params)
           ~~~~~~~~~~~~~~~^^^^^^^^^^^^^^^
django.db.utils.OperationalError: no such table: fair_agent_app_queryrecord
ERROR 2025-09-28 18:56:19,381 basehttp 38991 6255980544 "GET / HTTP/1.1" 500 149315
INFO 2025-09-28 18:57:50,382 finance_agent 39548 8680163328 Finance Agent loaded with model: gpt2
INFO 2025-09-28 18:57:50,838 medical_agent 39548 8680163328 Medical Agent loaded with model: gpt2
INFO 2025-09-28 18:57:50,838 orchestrator 39548 8680163328 Orchestrator initialized successfully
WARNING 2025-09-28 18:57:50,838 faithfulness 39548 8680163328 sentence-transformers not available, using token-based metrics only
WARNING 2025-09-28 18:57:50,838 safety 39548 8680163328 Safety config not found: /Users/somesh/Library/CloudStorage/OneDrive-PaceUniversity/Fair-Agent/config/safety_keywords.yaml
INFO 2025-09-28 18:57:50,838 services 39548 8680163328 FAIR-Agent system initialized successfully
INFO 2025-09-28 18:58:04,261 finance_agent 39888 8680163328 Finance Agent loaded with model: gpt2
INFO 2025-09-28 18:58:04,763 medical_agent 39888 8680163328 Medical Agent loaded with model: gpt2
INFO 2025-09-28 18:58:04,763 orchestrator 39888 8680163328 Orchestrator initialized successfully
WARNING 2025-09-28 18:58:04,763 faithfulness 39888 8680163328 sentence-transformers not available, using token-based metrics only
WARNING 2025-09-28 18:58:04,764 safety 39888 8680163328 Safety config not found: /Users/somesh/Library/CloudStorage/OneDrive-PaceUniversity/Fair-Agent/config/safety_keywords.yaml
INFO 2025-09-28 18:58:04,764 services 39888 8680163328 FAIR-Agent system initialized successfully
INFO 2025-09-28 18:58:08,289 finance_agent 39907 8680163328 Finance Agent loaded with model: gpt2
INFO 2025-09-28 18:58:08,783 medical_agent 39907 8680163328 Medical Agent loaded with model: gpt2
INFO 2025-09-28 18:58:08,783 orchestrator 39907 8680163328 Orchestrator initialized successfully
WARNING 2025-09-28 18:58:08,783 faithfulness 39907 8680163328 sentence-transformers not available, using token-based metrics only
WARNING 2025-09-28 18:58:08,784 safety 39907 8680163328 Safety config not found: /Users/somesh/Library/CloudStorage/OneDrive-PaceUniversity/Fair-Agent/config/safety_keywords.yaml
INFO 2025-09-28 18:58:08,784 services 39907 8680163328 FAIR-Agent system initialized successfully
INFO 2025-09-28 18:58:08,798 autoreload 39907 8680163328 Watching for file changes with StatReloader
INFO 2025-09-28 18:58:25,110 basehttp 39907 6163476480 "GET / HTTP/1.1" 200 16512
INFO 2025-09-28 18:58:25,541 basehttp 39907 6163476480 "GET / HTTP/1.1" 200 16512
INFO 2025-09-28 18:58:33,243 basehttp 39907 6163476480 "GET /query/ HTTP/1.1" 200 56562
ERROR 2025-09-28 18:58:55,329 robustness 39907 6163476480 Error evaluating robustness: 'str' object is not callable
INFO 2025-09-28 18:58:55,333 basehttp 39907 6163476480 "POST /api/query/process/ HTTP/1.1" 200 1370
INFO 2025-09-28 18:59:21,782 basehttp 39907 6180302848 "GET /?id=6922b48c-a19b-43c5-b4dc-fec650371f80&vscodeBrowserReqId=1759085961776 HTTP/1.1" 200 16512
